<?xml version="1.0"?>
<robot name="maxon_epos4" xmlns:xarco="http://www.ros.org/wiki/xacro">
  
  <!-- Base link -->
  <link name="base_link">
  </link>

  <!-- Link1 Link-->
  <link name="link1_link">
  </link>

  <!-- Joint between Base and Link1 -->

  <joint name="base_link1_joint" type="revolute">
     <parent link="base_link"/>
     <child link="link1_link"/>
     <origin xyz="0 0 0" rpy="0 0 0"/>
     <axis xyz="1 0 0"/>
     <!--<dynamics dampning="0.7"/>-->
     <limit effort="100.0" velocity="1300" lower="0" upper="10000"/>
  </joint>
  
  <!-- Link2 link -->
  <link name="link2_link">
  </link>

  <!-- Joint between base and link2 -->
  <joint name="base_link2_joint" type="revolute">
    <parent link="base_link"/>
    <child link="link2_link"/>
    <origin xyz="0 0 0" rpy="0 0 0"/>
    <axis xyz="1 0 0"/>
   <!-- <dynamics dampning="0.7"/> -->
    <limit effort="100.0" velocity="1300" lower="0" upper="10000"/> 
  </joint>

  <transmission name="transmission_base_link1">
    <type>transmission_interface/SimpleTransmission</type>
    <joint name="base_link1_joint">
      <hardwareInterface>hardware_interface/EffortJointInterface</hardwareInterface>
    </joint>
    <actuator name="link1_maxon_motor">
      <hardwareInterface>EffortJointInterface</hardwareInterface>
      <mechanicalReduction>1</mechanicalReduction>
    </actuator>
  </transmission>

  <transmission name="transmission_base_link2">
    <type>transmission_interface/SimpleTransmission</type>
    <joint name="base_link2_joint">
      <hardwareInterface>hardware_interface/EffortJointInterface</hardwareInterface>
    </joint>
    <actuator>
      <hardwareInterface>EffortJointInterface</hardwareInterface>
      <mechanicalReduction>1</mechanicalReduction>
    </actuator>
  </transmission>

</robot>
